Failure # 1 (occurred at 2023-08-09_15-57-37)
The actor died because of an error raised in its creation task, [36mray::DQN.__init__()[39m (pid=27492, ip=10.221.31.228, actor_id=bc38c5dafb40fcd25c95ed6701000000, repr=DQN)
  File "/home/vamsi/PycharmProjects/rl-sumo/lib/python3.7/site-packages/ray/rllib/evaluation/worker_set.py", line 244, in _setup
    validate=config.validate_workers_after_construction,
  File "/home/vamsi/PycharmProjects/rl-sumo/lib/python3.7/site-packages/ray/rllib/evaluation/worker_set.py", line 635, in add_workers
    raise result.get()
  File "/home/vamsi/PycharmProjects/rl-sumo/lib/python3.7/site-packages/ray/rllib/utils/actor_manager.py", line 488, in __fetch_result
    result = ray.get(r)
ray.exceptions.RayActorError: The actor died because of an error raised in its creation task, [36mray::RolloutWorker.__init__()[39m (pid=27549, ip=10.221.31.228, actor_id=47835f44d8792a7f9123a8e401000000, repr=<ray.rllib.evaluation.rollout_worker.RolloutWorker object at 0x7f3a502ec090>)
  File "/home/vamsi/Documents/GitHub/rl-sumo/rlsumo/envs/ringroad.py", line 35, in reset
    self.vehicle_kernel.reset(self.kernel_api, track_len)
  File "/home/vamsi/Documents/GitHub/rl-sumo/rlsumo/vehicle/VehicleKernel.py", line 31, in reset
    self._initialize_state()
  File "/home/vamsi/Documents/GitHub/rl-sumo/rlsumo/vehicle/VehicleKernel.py", line 59, in _initialize_state
    self._create_vehicles(gap_req, total_num, num_rl_vehicles)
  File "/home/vamsi/Documents/GitHub/rl-sumo/rlsumo/vehicle/VehicleKernel.py", line 144, in _create_vehicles
    track_len=self.track_length
  File "/home/vamsi/Documents/GitHub/rl-sumo/rlsumo/vehicle/vehicle.py", line 93, in __init__
    routes, failsafe, leader_id, action_type, track_len)
TypeError: __init__() missing 1 required positional argument: 'track_len'

The above exception was the direct cause of the following exception:

[36mray::RolloutWorker.__init__()[39m (pid=27549, ip=10.221.31.228, actor_id=47835f44d8792a7f9123a8e401000000, repr=<ray.rllib.evaluation.rollout_worker.RolloutWorker object at 0x7f3a502ec090>)
  File "/home/vamsi/PycharmProjects/rl-sumo/lib/python3.7/site-packages/ray/rllib/utils/pre_checks/env.py", line 81, in check_env
    check_gym_environments(env)
  File "/home/vamsi/PycharmProjects/rl-sumo/lib/python3.7/site-packages/ray/rllib/utils/pre_checks/env.py", line 174, in check_gym_environments
    ) from e
ValueError: Your gymnasium.Env's `reset()` method raised an Exception!

During handling of the above exception, another exception occurred:

[36mray::RolloutWorker.__init__()[39m (pid=27549, ip=10.221.31.228, actor_id=47835f44d8792a7f9123a8e401000000, repr=<ray.rllib.evaluation.rollout_worker.RolloutWorker object at 0x7f3a502ec090>)
  File "/home/vamsi/PycharmProjects/rl-sumo/lib/python3.7/site-packages/ray/rllib/evaluation/rollout_worker.py", line 616, in __init__
    check_env(self.env)
  File "/home/vamsi/PycharmProjects/rl-sumo/lib/python3.7/site-packages/ray/rllib/utils/pre_checks/env.py", line 93, in check_env
    f"{actual_error}\n"
ValueError: Traceback (most recent call last):
  File "/home/vamsi/PycharmProjects/rl-sumo/lib/python3.7/site-packages/ray/rllib/utils/pre_checks/env.py", line 170, in check_gym_environments
    env.reset()
  File "/home/vamsi/Documents/GitHub/rl-sumo/rlsumo/envs/ringroad.py", line 35, in reset
    self.vehicle_kernel.reset(self.kernel_api, track_len)
  File "/home/vamsi/Documents/GitHub/rl-sumo/rlsumo/vehicle/VehicleKernel.py", line 31, in reset
    self._initialize_state()
  File "/home/vamsi/Documents/GitHub/rl-sumo/rlsumo/vehicle/VehicleKernel.py", line 59, in _initialize_state
    self._create_vehicles(gap_req, total_num, num_rl_vehicles)
  File "/home/vamsi/Documents/GitHub/rl-sumo/rlsumo/vehicle/VehicleKernel.py", line 144, in _create_vehicles
    track_len=self.track_length
  File "/home/vamsi/Documents/GitHub/rl-sumo/rlsumo/vehicle/vehicle.py", line 93, in __init__
    routes, failsafe, leader_id, action_type, track_len)
TypeError: __init__() missing 1 required positional argument: 'track_len'

The above exception was the direct cause of the following exception:

[36mray::RolloutWorker.__init__()[39m (pid=27549, ip=10.221.31.228, actor_id=47835f44d8792a7f9123a8e401000000, repr=<ray.rllib.evaluation.rollout_worker.RolloutWorker object at 0x7f3a502ec090>)
  File "/home/vamsi/PycharmProjects/rl-sumo/lib/python3.7/site-packages/ray/rllib/utils/pre_checks/env.py", line 81, in check_env
    check_gym_environments(env)
  File "/home/vamsi/PycharmProjects/rl-sumo/lib/python3.7/site-packages/ray/rllib/utils/pre_checks/env.py", line 174, in check_gym_environments
    ) from e
ValueError: Your gymnasium.Env's `reset()` method raised an Exception!

The above error has been found in your environment! We've added a module for checking your custom environments. It may cause your experiment to fail if your environment is not set up correctly. You can disable this behavior via calling `config.environment(disable_env_checking=True)`. You can run the environment checking module standalone by calling ray.rllib.utils.check_env([your env]).

During handling of the above exception, another exception occurred:

[36mray::DQN.__init__()[39m (pid=27492, ip=10.221.31.228, actor_id=bc38c5dafb40fcd25c95ed6701000000, repr=DQN)
  File "/home/vamsi/PycharmProjects/rl-sumo/lib/python3.7/site-packages/ray/rllib/algorithms/algorithm.py", line 478, in __init__
    **kwargs,
  File "/home/vamsi/PycharmProjects/rl-sumo/lib/python3.7/site-packages/ray/tune/trainable/trainable.py", line 170, in __init__
    self.setup(copy.deepcopy(self.config))
  File "/home/vamsi/PycharmProjects/rl-sumo/lib/python3.7/site-packages/ray/rllib/algorithms/algorithm.py", line 608, in setup
    logdir=self.logdir,
  File "/home/vamsi/PycharmProjects/rl-sumo/lib/python3.7/site-packages/ray/rllib/evaluation/worker_set.py", line 194, in __init__
    raise e.args[0].args[2]
ValueError: Traceback (most recent call last):
  File "/home/vamsi/PycharmProjects/rl-sumo/lib/python3.7/site-packages/ray/rllib/utils/pre_checks/env.py", line 170, in check_gym_environments
    env.reset()
  File "/home/vamsi/Documents/GitHub/rl-sumo/rlsumo/envs/ringroad.py", line 35, in reset
    self.vehicle_kernel.reset(self.kernel_api, track_len)
  File "/home/vamsi/Documents/GitHub/rl-sumo/rlsumo/vehicle/VehicleKernel.py", line 31, in reset
    self._initialize_state()
  File "/home/vamsi/Documents/GitHub/rl-sumo/rlsumo/vehicle/VehicleKernel.py", line 59, in _initialize_state
    self._create_vehicles(gap_req, total_num, num_rl_vehicles)
  File "/home/vamsi/Documents/GitHub/rl-sumo/rlsumo/vehicle/VehicleKernel.py", line 144, in _create_vehicles
    track_len=self.track_length
  File "/home/vamsi/Documents/GitHub/rl-sumo/rlsumo/vehicle/vehicle.py", line 93, in __init__
    routes, failsafe, leader_id, action_type, track_len)
TypeError: __init__() missing 1 required positional argument: 'track_len'

The above exception was the direct cause of the following exception:

[36mray::DQN.__init__()[39m (pid=27492, ip=10.221.31.228, actor_id=bc38c5dafb40fcd25c95ed6701000000, repr=DQN)
  File "/home/vamsi/PycharmProjects/rl-sumo/lib/python3.7/site-packages/ray/rllib/utils/pre_checks/env.py", line 81, in check_env
    check_gym_environments(env)
  File "/home/vamsi/PycharmProjects/rl-sumo/lib/python3.7/site-packages/ray/rllib/utils/pre_checks/env.py", line 174, in check_gym_environments
    ) from e
ValueError: Your gymnasium.Env's `reset()` method raised an Exception!

The above error has been found in your environment! We've added a module for checking your custom environments. It may cause your experiment to fail if your environment is not set up correctly. You can disable this behavior via calling `config.environment(disable_env_checking=True)`. You can run the environment checking module standalone by calling ray.rllib.utils.check_env([your env]).
